Workbook

Sheet Велком 19.05
A5: Кейтеринг- меню 2026
A6: Менеджер службы кейтеринга | D6: Мероприятие | F6: Тайминг | I6: Выбранный зал
F7: Сбор гостей | G7: Начало | H7: Окон чание
A8: Лесников Михаил | D8: Кофе Брейк | I8: СБЕР, Советская 34
A9: Дата проведения | B9: Рассадка | D9: Кол-во | E9: Аванс | F9: Дата внесения | G9: Форма оплаты | I9: Контактный телефон
A10: 46161 | D10: 130
A11: ФИО заказчика/ наименование организации | E11: E-mail | I11: Примечания
A12: Ольга Лукина
A13: Выпечка
A14: Наименование | E14: Выход /гр | F14: Грамм /чел | G14: Цена | H14: Кол-во | I14: Сумма
A15: Мини-пирожки
A16: Мини-пышка с брусникой | E16: 22 | F16: =E16*H16/$D$10 -> 13.538462 | G16: 40 | H16: 80 | I16: =G16*H16 -> 3200 | J16: Сектора | K16: Сектора
A17: Мини-пышки / мясом | E17: 22 | F17: =E17*H17/$D$10 -> 13.538462 | G17: 35 | H17: 80 | I17: =G17*H17 -> 2800 | J17: Сектора
A18: Мини-пышки / яйцом | E18: 22 | F18: =E18*H18/$D$10 -> 13.538462 | G18: 35 | H18: 80 | I18: =G18*H18 -> 2800 | J18: Сектора
A19: СЭНДВИЧИ
A20: Наименование | E20: Выход /гр | F20: Грамм /чел | G20: Цена | H20: Кол-во | I20: Сумма
A21: 1/2 сендвича с курицей | B21: Каравай | C21: Каравай | D21: Каравай | E21: 75 | F21: =E21*H21/$D$10 -> 46.153846 | G21: 130 | H21: 80 | I21: =H21*G21 -> 10400 | J21: Сектора | K21: Сектора
A22: 1/2 сендвича с паштетом из тунца | B22: Каравай | C22: Каравай | D22: Каравай | E22: 75 | F22: =E22*H22/$D$10 -> 46.153846 | G22: 170 | H22: 80 | I22: =H22*G22 -> 13600 | J22: Сектора
A23: ДЕСЕРТЫ
A24: Наименование | E24: Выход /гр | F24: Грамм /чел | G24: Цена | H24: Кол-во | I24: Сумма
A25: Мини-брауни | B25: Палочки бисквитные к шоколадному фонтану | C25: Палочки бисквитные к шоколадному фонтану | D25: Палочки бисквитные к шоколадному фонтану | E25: 50 | F25: =E25*H25/$D$10 -> 30.769231 | G25: 80 | H25: 80 | I25: =H25*G25 -> 6400 | J25: Сектора | K25: Сектора
A26: Мини-Опера | B26: Палочки бисквитные к шоколадному фонтану | C26: Палочки бисквитные к шоколадному фонтану | D26: Палочки бисквитные к шоколадному фонтану | E26: 55 | F26: =E26*H26/$D$10 -> 33.846154 | G26: 90 | H26: 80 | I26: =H26*G26 -> 7200 | J26: Сектора
A27: Фрукты
A28: Наименование | E28: Выход /гр | F28: Грамм /чел | G28: Цена | H28: Кол-во | I28: Сумма
A29: Яблоки сезонные ( маленькие ) | E29: 100 | F29: =E29*H29/$D$10 -> 76.923077 | G29: 35 | H29: 100 | I29: =H29*G29 -> 3500
A30: Бананы мини | E30: 100 | F30: =E30*H30/$D$10 -> 76.923077 | G30: 75 | H30: 100 | I30: =H30*G30 -> 7500 | K30: сектора
A31: Слива | E31: 100 | F31: =E31*H31/$D$10 -> 46.153846 | G31: 180 | H31: 60 | I31: =H31*G31 -> 10800
A32: Лимон нарезка | E32: 100 | F32: =E32*H32/$D$10 -> 30.769231 | G32: 90 | H32: 40 | I32: =H32*G32 -> 3600
A33: Итого кухня | J33: =SUM(I13:I32) -> 71800
A34: Итого грамм на персону без напитков | J34: =SUM(F13:F30) -> 351.38462
A35: Безалкогольные напитки
A36: Наименование | E36: Выход /гр | F36: Грамм /чел | G36: Цена | H36: Кол-во | I36: Сумма
A37: Чай пакетированный | E37: 200 | G37: 35 | H37: 80 | I37: =G37*H37 -> 2800
A38: Кофе "Эспрессо", "Американо" | E38: 30/120 | G38: 100 | H38: 100 | I38: =G38*H38 -> 10000
A39: Сливки порционные | E39: 10 | G39: 20 | H39: 100 | I39: =G39*H39 -> 2000
A40: Итого бар | J40: =SUM(I37:I39) -> 14800
A41: Аренда, услуги, логистика | J41: 11600
A42: ИТОГО ПО ВСЕМ РАЗДЕЛАМ | J42: =J33+J40+J41 -> 98200
A43: Итого по всем разделам на персону | J43: =J42/$D$10 -> 755.38462

Sheet Кофе Брейк обед 19.05
A5: Кейтеринг- меню 2026
A6: Менеджер службы кейтеринга | D6: Мероприятие | F6: Тайминг | I6: Выбранный зал
F7: Сбор гостей | G7: Начало | H7: Окон чание
A8: Лесников Михаил | D8: Кофе Брейк | I8: СБЕР, Советская 34
A9: Дата проведения | B9: Рассадка | D9: Кол-во | E9: Аванс | F9: Дата внесения | G9: Форма оплаты | I9: Контактный телефон
A10: 46161 | D10: 130
A11: ФИО заказчика/ наименование организации | E11: E-mail | I11: Примечания
A12: Ольга Лукина
A13: Фуршетные закуски
A14: Наименование | E14: Выход /гр | F14: Грамм /чел | G14: Цена | H14: Кол-во | I14: Сумма
A15: Мини-пирожки
A16: Блинчик с курицей | E16: 75 | F16: =E16*H16/$D$10 -> 46.153846 | G16: 120 | H16: 80 | I16: =G16*H16 -> 9600 | K16: Мармит
A17: Блинчик с творогом | E17: 75 | F17: =E17*H17/$D$10 -> 46.153846 | G17: 80 | H17: 80 | I17: =G17*H17 -> 6400
A18: Блин со сметаной | E18: 80 | F18: =E18*H18/$D$10 -> 49.230769 | G18: 80 | H18: 80 | I18: =G18*H18 -> 6400
A19: Десерт
A20: Наименование | E20: Выход /гр | F20: Грамм /чел | G20: Цена | H20: Кол-во | I20: Сумма
A21: Маффин шоколадный | E21: 50 | F21: =E21*H21/$D$10 -> 26.923077 | G21: 50 | H21: 70 | I21: =H21*G21 -> 3500
A22: Маффин с черникой | E22: 80 | F22: =E22*H22/$D$10 -> 43.076923 | G22: 60 | H22: 70 | I22: =H22*G22 -> 4200 | K22: Поднос
A23: Мини-брауни | B23: Палочки бисквитные к шоколадному фонтану | C23: Палочки бисквитные к шоколадному фонтану | D23: Палочки бисквитные к шоколадному фонтану | E23: 50 | F23: =E23*H23/$D$10 -> 26.923077 | G23: 80 | H23: 70 | I23: =H23*G23 -> 5600
A24: Выпечка, бутерброды
A25: Наименование | E25: Выход /гр | F25: Грамм /чел | G25: Цена | H25: Кол-во | I25: Сумма
A26: Мини-пирожки
A27: Мини-пирожок с капустой и яйцом | E27: 30 | F27: =E27*H27/$D$10 -> 16.153846 | G27: 30 | H27: 70 | I27: =H27*G27 -> 2100
A28: Мини-пирожки с картофелем | E28: 30 | F28: =E28*H28/$D$10 -> 16.153846 | G28: 30 | H28: 70 | I28: =H28*G28 -> 2100 | K28: поднос
A29: Мини-пирожки с мясом | E29: 30 | F29: =E29*H29/$D$10 -> 16.153846 | G29: 50 | H29: 70 | I29: =H29*G29 -> 3500
A30: Минни пицца | E30: 90 | F30: =E30*H30/$D$10 -> 48.461538 | G30: 120 | H30: 70 | I30: =H30*G30 -> 8400
A31: ФРУКТЫ
A32: Лимон в нарезке | E32: 100 | F32: =H32*E32/D10 -> 30.769231 | G32: 90 | H32: 40 | I32: =H32*G32 -> 3600
A33: Яблоки сезонные | E33: 100 | F33: =E33*H33/$D$10 -> 61.538462 | G33: 35 | H33: 80 | I33: =H33*G33 -> 2800
A34: Бананы мини | E34: 100 | F34: =E34*H34/$D$10 -> 61.538462 | G34: 75 | H34: 80 | I34: =H34*G34 -> 6000
A35: Слива | E35: 100 | F35: =E35*H35/$D$10 -> 30.769231 | G35: 180 | H35: 40 | I35: =H35*G35 -> 7200
A36: Итого кухня | J36: =SUM(I15:I35) -> 71400
A37: Итого грамм на персону без напитков | J37: =SUM(F13:F35) -> 520
A38: Безалкогольные напитки
A39: Наименование | E39: Выход /гр | F39: Грамм /чел | G39: Цена | H39: Кол-во | I39: Сумма
A40: Чай пакетированный | E40: 200 | G40: 35 | H40: 80 | I40: =G40*H40 -> 2800
A41: Кофе "Эспрессо", "Американо" | E41: 30/120 | G41: 100 | H41: 100 | I41: =G41*H41 -> 10000
A42: Сливки порционные | E42: 10 | G42: 20 | H42: 100 | I42: =G42*H42 -> 2000
A43: Итого бар | J43: =SUM(I40:I42) -> 14800
A44: Аренда, услуги, логистика | J44: 11600
...

Sheet Кофе Брейк полдник 19.05
A5: Кейтеринг- меню 2026
A6: Менеджер службы кейтеринга | D6: Мероприятие | F6: Тайминг | I6: Выбранный зал
F7: Сбор гостей | G7: Начало | H7: Окон чание
A8: Лесников Михаил | D8: Кофе Брейк | G8: 0.625 | I8: СБЕР, Советская 34
A9: Дата проведения | B9: Рассадка | D9: Кол-во | E9: Аванс | F9: Дата внесения | G9: Форма оплаты | I9: Контактный телефон
A10: 46161 | D10: 130
A11: ФИО заказчика/ наименование организации | E11: E-mail | I11: Примечания
A12: Ольга Лукина
A13: Фуршетные закуски
A14: Наименование | E14: Выход /гр | F14: Грамм /чел | G14: Цена | H14: Кол-во | I14: Сумма
A15: Мини-пирожки
A16: Рафаэлло /Нежный паштет из цыпленка, огурцов и сыра "Рикотта" и "Грана Падано"/ | E16: 35 | F16: 0 | G16: 150 | H16: 80 | I16: =G16*H16 -> 12000 | K16: Этажерки
A17: Мясная закуска из ростбифа, телячьего языка и кремом из сыра Филадельфия | E17: 30 | F17: 0 | G17: 160 | H17: 80 | I17: =G17*H17 -> 12800
A18: Наполеон с курицей | E18: 60 | F18: 0 | G18: 80 | H18: 80 | I18: =G18*H18 -> 6400
A19: Десерт
A20: Наименование | E20: Выход /гр | F20: Грамм /чел | G20: Цена | H20: Кол-во | I20: Сумма
A21: Мини-Опера | E21: 55 | F21: 0 | G21: 90 | H21: 70 | I21: =H21*G21 -> 6300
A22: Мини-Красный бархат | E22: 60 | F22: 0 | G22: 90 | H22: 70 | I22: =H22*G22 -> 6300
A23: Безе | E23: 5 | F23: 0 | G23: 10 | H23: 200 | I23: =H23*G23 -> 2000
A24: Мини-брауни | B24: Палочки бисквитные к шоколадному фонтану | C24: Палочки бисквитные к шоколадному фонтану | D24: Палочки бисквитные к шоколадному фонтану | E24: 50 | F24: =E24*H24/$D$10 -> 26.923077 | G24: 80 | H24: 70 | I24: =H24*G24 -> 5600
A25: Выпечка, бутерброды
A26: Наименование | E26: Выход /гр | F26: Грамм /чел | G26: Цена | H26: Кол-во | I26: Сумма
A27: Мини-пирожки
A28: Мини-пирожок с капустой и яйцом | E28: 30 | F28: =E28*H28/$D$10 -> 16.153846 | G28: 30 | H28: 70 | I28: =H28*G28 -> 2100
A29: Мини-пирожки с картофелем | E29: 30 | F29: =E29*H29/$D$10 -> 16.153846 | G29: 30 | H29: 70 | I29: =H29*G29 -> 2100
A30: Мини-пирожки с мясом | E30: 30 | F30: =E30*H30/$D$10 -> 16.153846 | G30: 50 | H30: 70 | I30: =H30*G30 -> 3500
A31: Нон с сыром | E31: 90 | F31: =E31*H31/$D$10 -> 48.461538 | G31: 110 | H31: 70 | I31: =H31*G31 -> 7700
A32: ФРУКТЫ
A33: Лимон в нарезке | E33: 100 | F33: =H33*E33/D10 -> 30.769231 | G33: 90 | H33: 40 | I33: =H33*G33 -> 3600
A34: Яблоки сезонные | E34: 100 | F34: =E34*H34/$D$10 -> 61.538462 | G34: 35 | H34: 80 | I34: =H34*G34 -> 2800 | K34: Этажерка 3 Яруса
A35: Бананы мини | E35: 100 | F35: =E35*H35/$D$10 -> 61.538462 | G35: 75 | H35: 80 | I35: =H35*G35 -> 6000
A36: Слива | E36: 100 | F36: =E36*H36/$D$10 -> 30.769231 | G36: 180 | H36: 40 | I36: =H36*G36 -> 7200
A37: Итого кухня | J37: =SUM(I15:I36) -> 86400
A38: Итого грамм на персону без напитков | J38: =SUM(F13:F36) -> 308.46154
A39: Безалкогольные напитки
A40: Наименование | E40: Выход /гр | F40: Грамм /чел | G40: Цена | H40: Кол-во | I40: Сумма
A41: Чай пакетированный | E41: 200 | G41: 35 | H41: 80 | I41: =G41*H41 -> 2800
A42: Кофе "Эспрессо", "Американо" | E42: 30/120 | G42: 100 | H42: 100 | I42: =G42*H42 -> 10000
A43: Сливки порционные | E43: 10 | G43: 20 | H43: 100 | I43: =G43*H43 -> 2000
A44: Итого бар | J44: =SUM(I41:I43) -> 14800
...

Sheet Велком 20.05
A5: Кейтеринг- меню 2026
A6: Менеджер службы кейтеринга | D6: Мероприятие | F6: Тайминг | I6: Выбранный зал
F7: Сбор гостей | G7: Начало | H7: Окон чание
A8: Лесников Михаил | D8: Кофе Брейк | I8: СБЕР, Советская 34
A9: Дата проведения | B9: Рассадка | D9: Кол-во | E9: Аванс | F9: Дата внесения | G9: Форма оплаты | I9: Контактный телефон
A10: 46162 | D10: 130
A11: ФИО заказчика/ наименование организации | E11: E-mail | I11: Примечания
A12: Ольга Лукина
A13: Выпечка
A14: Наименование | E14: Выход /гр | F14: Грамм /чел | G14: Цена | H14: Кол-во | I14: Сумма
A15: Мини-пирожки
A16: Сырники со сметаной | E16: 100 | F16: =E16*H16/$D$10 -> 53.846154 | G16: 120 | H16: 70 | I16: =G16*H16 -> 8400 | K16: Мармит
A17: Мини-пышки / мясом | E17: 22 | F17: =E17*H17/$D$10 -> 11.846154 | G17: 35 | H17: 70 | I17: =G17*H17 -> 2450
A18: Мини-пирожки с картофелем | E18: 30 | F18: =E18*H18/$D$10 -> 16.153846 | G18: 30 | H18: 70 | I18: =G18*H18 -> 2100
A19: СЭНДВИЧИ
A20: Наименование | E20: Выход /гр | F20: Грамм /чел | G20: Цена | H20: Кол-во | I20: Сумма
A21: 1/2 сендвича с ветчиной и сыром | B21: Каравай | C21: Каравай | D21: Каравай | E21: 75 | F21: =E21*H21/$D$10 -> 40.384615 | G21: 180 | H21: 70 | I21: =H21*G21 -> 12600
A22: 1/2 сендвича с индейкой и беконом | E22: 75 | F22: =E22*H22/$D$10 -> 40.384615 | G22: 130 | H22: 70 | I22: =H22*G22 -> 9100 | K22: Сектора
A23: ДЕСЕРТЫ
A24: Наименование | E24: Выход /гр | F24: Грамм /чел | G24: Цена | H24: Кол-во | I24: Сумма
A25: Мини-Красный бархат | B25: Палочки бисквитные к шоколадному фонтану | C25: Палочки бисквитные к шоколадному фонтану | D25: Палочки бисквитные к шоколадному фонтану | E25: 60 | F25: =E25*H25/$D$10 -> 32.307692 | G25: 90 | H25: 70 | I25: =H25*G25 -> 6300
A26: Мини-медовик | E26: 50 | F26: 0 | G26: 60 | H26: 70 | I26: =H26*G26 -> 4200 | K26: сектора
A27: Фрукты
A28: Наименование | E28: Выход /гр | F28: Грамм /чел | G28: Цена | H28: Кол-во | I28: Сумма
A29: Яблоки сезонные ( маленькие ) | E29: 100 | F29: =E29*H29/$D$10 -> 61.538462 | G29: 35 | H29: 80 | I29: =H29*G29 -> 2800
A30: Бананы мини | E30: 100 | F30: =E30*H30/$D$10 -> 61.538462 | G30: 75 | H30: 80 | I30: =H30*G30 -> 6000 | K30: сектора
A31: Слива | E31: 100 | F31: =E31*H31/$D$10 -> 46.153846 | G31: 180 | H31: 60 | I31: =H31*G31 -> 10800
A32: Лимон нарезка | E32: 100 | F32: =E32*H32/$D$10 -> 30.769231 | G32: 90 | H32: 40 | I32: =H32*G32 -> 3600
A33: Итого кухня | J33: =SUM(I13:I32) -> 68350
A34: Итого грамм на персону без напитков | J34: =SUM(F13:F30) -> 318
A35: Безалкогольные напитки
A36: Наименование | E36: Выход /гр | F36: Грамм /чел | G36: Цена | H36: Кол-во | I36: Сумма
A37: Чай пакетированный | E37: 200 | G37: 35 | H37: 80 | I37: =G37*H37 -> 2800
A38: Кофе "Эспрессо", "Американо" | E38: 30/120 | G38: 100 | H38: 100 | I38: =G38*H38 -> 10000
A39: Сливки порционные | E39: 10 | G39: 20 | H39: 100 | I39: =G39*H39 -> 2000
A40: Итого бар | J40: =SUM(I37:I39) -> 14800
A41: Аренда, услуги, логистика | J41: 11600
A42: ИТОГО ПО ВСЕМ РАЗДЕЛАМ | J42: =J33+J40+J41 -> 94750
A43: Итого по всем разделам на персону | J43: =J42/$D$10 -> 728.84615

Sheet Кофе Брейк обед 20.05
A5: Кейтеринг- меню 2026
A6: Менеджер службы кейтеринга | D6: Мероприятие | F6: Тайминг | I6: Выбранный зал
F7: Сбор гостей | G7: Начало | H7: Окон чание
A8: Лесников Михаил | D8: Кофе Брейк | I8: СБЕР, Советская 34
A9: Дата проведения | B9: Рассадка | D9: Кол-во | E9: Аванс | F9: Дата внесения | G9: Форма оплаты | I9: Контактный телефон
A10: 46162 | D10: 130
A11: ФИО заказчика/ наименование организации | E11: E-mail | I11: Примечания
A12: Ольга Лукина
A13: Десерт
A14: Блин с мясом | E14: 52 | F14: =H14*E14/D10 -> 28 | G14: 215 | H14: 70 | I14: =H14*G14 -> 15050 | K14: Мармиты
A15: Блин розовый с вялеными томатами и сливочным сыром | E15: 20 | F15: =H15*E15/D10 -> 10.769231 | G15: 75 | H15: 70 | I15: =H15*G15 -> 5250 | K15: возвышения +волна
A16: Десерт
A17: Наименование | E17: Выход /гр | F17: Грамм /чел | G17: Цена | H17: Кол-во | I17: Сумма
A18: Корзиночка песочная мини с мандариновым мармеладом | E18: 19 | F18: =H18*E18/$D$10 -> 8.7692308 | G18: 55 | H18: 60 | I18: =H18*G18 -> 3300 | K18: возвышения +волна
A19: Мини-капкейки в ассортименте/Лесная Ягода,Манго, с Сырным кремом/ | E19: 35 | F19: =H19*E19/$D$10 -> 16.153846 | G19: 90 | H19: 60 | I19: =H19*G19 -> 5400 | K19: возвышения +волна
A20: Макрони в ассортименте | E20: 15 | F20: 0 | G20: 80 | H20: 60 | I20: =H20*G20 -> 4800 | K20: возвышения +волна
A22: Круассан с вареной сгущенкой | E22: 80 | F22: =E22*H22/$D$10 -> 43.076923 | G22: 85 | H22: 70 | I22: =H22*G22 -> 5950 | K22: волна
A23: Слойка с яблоком и изюмом | E23: 80 | F23: =E23*H23/$D$10 -> 43.076923 | G23: 150 | H23: 70 | I23: =H23*G23 -> 10500 | K23: волна
A24: Выпечка, бутерброды
A25: Наименование | E25: Выход /гр | F25: Грамм /чел | G25: Цена | H25: Кол-во | I25: Сумма
A26: Мини-пирожки
A27: Пирог печеный с яйцом | E27: 30 | F27: =E27*H27/$D$10 -> 16.153846 | G27: 30 | H27: 70 | I27: =H27*G27 -> 2100 | K27: волна
A28: Мини-пирожки с картофелем | E28: 30 | F28: =E28*H28/$D$10 -> 16.153846 | G28: 30 | H28: 70 | I28: =H28*G28 -> 2100 | K28: волна
A29: Мини-пирожок с творогом и вишней | E29: 30 | F29: =E29*H29/$D$10 -> 16.153846 | G29: 30 | H29: 70 | I29: =H29*G29 -> 2100 | K29: волна
A30: ФРУКТЫ
A31: Лимон в нарезке | E31: 100 | F31: =H31*E31/D10 -> 30.769231 | G31: 90 | H31: 40 | I31: =H31*G31 -> 3600
A32: Виноград | E32: 100 | F32: =H31*E32/D10 -> 30.769231 | G32: 200 | H32: 100 | I32: =H32*G32 -> 20000 | K32: вазы фруктовые
A33: Апельсин | E33: 100 | F33: =H33*E33/D10 -> 46.153846 | G33: 55 | H33: 60 | I33: =H33*G33 -> 3300
A34: Слива | E34: 100 | F34: =H34*E34/D10 -> 30.769231 | G34: 180 | H34: 40 | I34: =H34*G34 -> 7200
A35: Итого кухня | J35: =SUM(I13:I34) -> 90650
A36: Итого грамм на персону без напитков | J36: =SUM(F13:F34) -> 336.76923
A37: Безалкогольные напитки
A38: Наименование | E38: Выход /гр | F38: Грамм /чел | G38: Цена | H38: Кол-во | I38: Сумма
A39: Чай пакетированный | E39: 200 | G39: 35 | H39: 80 | I39: =G39*H39 -> 2800
A40: Кофе "Эспрессо", "Американо" | E40: 30/120 | G40: 100 | H40: 100 | I40: =G40*H40 -> 10000
A41: Сливки порционные | E41: 10 | G41: 20 | H41: 100 | I41: =G41*H41 -> 2000
A42: Итого бар | J42: =SUM(I39:I41) -> 14800
A43: Аренда, услуги, логистика | J43: 11600
A44: ИТОГО ПО ВСЕМ РАЗДЕЛАМ | J44: =J35+J42+J43 -> 117050
A45: Итого по всем разделам на персону | J45: =J44/$D$10 -> 900.38462

Sheet Велком 21.05
A5: Кейтеринг- меню 2026
A6: Менеджер службы кейтеринга | D6: Мероприятие | F6: Тайминг | I6: Выбранный зал
F7: Сбор гостей | G7: Начало | H7: Окон чание
A8: Лесников Михаил | D8: Кофе Брейк | I8: СБЕР, Советская 34
A9: Дата проведения | B9: Рассадка | D9: Кол-во | E9: Аванс | F9: Дата внесения | G9: Форма оплаты | I9: Контактный телефон
A10: 46163 | D10: 130
A11: ФИО заказчика/ наименование организации | E11: E-mail | I11: Примечания
A12: Ольга Лукина
A13: Выпечка
A14: Наименование | E14: Выход /гр | F14: Грамм /чел | G14: Цена | H14: Кол-во | I14: Сумма
A15: Мини-пирожки
A16: Пирожок с мясом | E16: 40 | F16: =E16*H16/$D$10 -> 18.461538 | G16: 110 | H16: 60 | I16: =G16*H16 -> 6600 | K16: Сектора
A17: Пирожок с капустой и яйцом | E17: 40 | F17: =E17*H17/$D$10 -> 18.461538 | G17: 110 | H17: 60 | I17: =G17*H17 -> 6600
A18: Пирожок с яблоком и корицей | E18: 40 | F18: =E18*H18/$D$10 -> 18.461538 | G18: 110 | H18: 60 | I18: =G18*H18 -> 6600
A19: СЭНДВИЧИ
A20: Наименование | E20: Выход /гр | F20: Грамм /чел | G20: Цена | H20: Кол-во | I20: Сумма
A21: 1/2 сендвича с курицей | B21: Каравай | C21: Каравай | D21: Каравай | E21: 75 | F21: =E21*H21/$D$10 -> 46.153846 | G21: 130 | H21: 80 | I21: =H21*G21 -> 10400 | K21: сектора
A22: 1/2 сендвича с паштетом из тунца | B22: Каравай | C22: Каравай | D22: Каравай | E22: 75 | F22: =E22*H22/$D$10 -> 43.269231 | G22: 170 | H22: 75 | I22: =H22*G22 -> 12750
A23: БУТЕРБРОДЫ
A24: Наименование | E24: Выход /гр | F24: Грамм /чел | G24: Цена | H24: Кол-во | I24: Сумма
A25: Бутерброд с бужениной | E25: 28 | F25: =E25*H25/$D$10 -> 12.923077 | G25: 90 | H25: 60 | I25: =H25*G25 -> 5400 | K25: сектора
A26: Бутерброд с индейкой | E26: 28 | F26: =E26*H26/$D$10 -> 12.923077 | G26: 70 | H26: 60 | I26: =H26*G26 -> 4200
A27: ДЕСЕРТЫ
A28: Наименование | E28: Выход /гр | F28: Грамм /чел | G28: Цена | H28: Кол-во | I28: Сумма
A29: Мини-Красный бархат | B29: Палочки бисквитные к шоколадному фонтану | C29: Палочки бисквитные к шоколадному фонтану | D29: Палочки бисквитные к шоколадному фонтану | E29: 60 | F29: =E29*H29/$D$10 -> 27.692308 | G29: 90 | H29: 60 | I29: =H29*G29 -> 5400 | K29: сектора
A30: Кукис шоколадный | E30: 30 | F30: =E30*H30/$D$10 -> 13.846154 | G30: 110 | H30: 60 | I30: =H30*G30 -> 6600
A31: Фрукты
A32: Наименование | E32: Выход /гр | F32: Грамм /чел | G32: Цена | H32: Кол-во | I32: Сумма
A33: Яблоки сезонные ( маленькие ) | E33: 100 | F33: =E33*H33/$D$10 -> 61.538462 | G33: 35 | H33: 80 | I33: =H33*G33 -> 2800
A34: Бананы мини | E34: 100 | F34: =E34*H34/$D$10 -> 61.538462 | G34: 75 | H34: 80 | I34: =H34*G34 -> 6000 | K34: сектора
A35: Слива | E35: 100 | F35: =E35*H35/$D$10 -> 30.769231 | G35: 180 | H35: 40 | I35: =H35*G35 -> 7200
A36: Лимон нарезка | E36: 100 | F36: =E36*H36/$D$10 -> 30.769231 | G36: 90 | H36: 40 | I36: =H36*G36 -> 3600
A37: Итого кухня | J37: =SUM(I13:I36) -> 84150
A38: Итого грамм на персону без напитков | J38: =SUM(F13:F34) -> 335.26923
A39: Безалкогольные напитки
A40: Наименование | E40: Выход /гр | F40: Грамм /чел | G40: Цена | H40: Кол-во | I40: Сумма
A41: Чай пакетированный | E41: 200 | G41: 35 | H41: 80 | I41: =G41*H41 -> 2800
A42: Кофе "Эспрессо", "Американо" | E42: 30/120 | G42: 100 | H42: 100 | I42: =G42*H42 -> 10000
A43: Сливки порционные | E43: 10 | G43: 20 | H43: 100 | I43: =G43*H43 -> 2000
A44: Итого бар | J44: =SUM(I41:I43) -> 14800
...

Sheet Кофе Брейк Обед 21.05
A5: Кейтеринг- меню 2026
A6: Менеджер службы кейтеринга | D6: Мероприятие | F6: Тайминг | I6: Выбранный зал
F7: Сбор гостей | G7: Начало | H7: Окон чание
A8: Лесников Михаил | D8: Кофе Брейк | I8: СБЕР, Советская 34
A9: Дата проведения | B9: Рассадка | D9: Кол-во | E9: Аванс | F9: Дата внесения | G9: Форма оплаты | I9: Контактный телефон
A10: 46163 | D10: 130
A11: ФИО заказчика/ наименование организации | E11: E-mail | I11: Примечания
A12: Ольга Лукина
A13: Фуршетные закуски
A14: Наименование | E14: Выход /гр | F14: Грамм /чел | G14: Цена | H14: Кол-во | I14: Сумма
A15: Мини-пирожки
A16: Круассан с ветчиной и творожным | E16: 90 | F16: =E16*H16/$D$10 -> 48.461538 | G16: 130 | H16: 70 | I16: =G16*H16 -> 9100
A17: Круассан с курицей и сладким соусом Чили | E17: 90 | F17: =E17*H17/$D$10 -> 48.461538 | G17: 110 | H17: 70 | I17: =G17*H17 -> 7700
A18: Смореброд с муссом из сома и чипсами из копченого сыра | E18: 40 | F18: =E18*H18/$D$10 -> 21.538462 | G18: 90 | H18: 70 | I18: =G18*H18 -> 6300
A19: Десерт
A20: Наименование | E20: Выход /гр | F20: Грамм /чел | G20: Цена | H20: Кол-во | I20: Сумма
A21: Кейк-попсы | E21: 30 | F21: =E21*H21/$D$10 -> 13.846154 | G21: 80 | H21: 60 | I21: =H21*G21 -> 4800
A22: Печенье овсяное | E22: 30 | F22: =E22*H22/$D$10 -> 13.846154 | G22: 30 | H22: 60 | I22: =H22*G22 -> 1800
A23: Мини-птичье молоко | B23: Палочки бисквитные к шоколадному фонтану | C23: Палочки бисквитные к шоколадному фонтану | D23: Палочки бисквитные к шоколадному фонтану | E23: 50 | F23: =E23*H23/$D$10 -> 23.076923 | G23: 65 | H23: 60 | I23: =H23*G23 -> 3900
A24: Выпечка, бутерброды
A25: Наименование | E25: Выход /гр | F25: Грамм /чел | G25: Цена | H25: Кол-во | I25: Сумма
A26: Мини-пирожки
A27: Мини-пирожок с капустой и яйцом | E27: 30 | F27: =E27*H27/$D$10 -> 13.846154 | G27: 30 | H27: 60 | I27: =H27*G27 -> 1800
A28: Мини-пирожки с картофелем | E28: 30 | F28: =E28*H28/$D$10 -> 13.846154 | G28: 30 | H28: 60 | I28: =H28*G28 -> 1800
A29: Мини-пирожки с мясом | E29: 30 | F29: =E29*H29/$D$10 -> 13.846154 | G29: 50 | H29: 60 | I29: =H29*G29 -> 3000
A30: Минни пицца | E30: 90 | F30: =E30*H30/$D$10 -> 41.538462 | G30: 120 | H30: 60 | I30: =H30*G30 -> 7200
A31: ФРУКТЫ
A32: Лимон в нарезке | E32: 100 | F32: =H32*E32/D10 -> 30.769231 | G32: 90 | H32: 40 | I32: =H32*G32 -> 3600
A33: Яблоки сезонные | E33: 100 | F33: =E33*H33/$D$10 -> 53.846154 | G33: 35 | H33: 70 | I33: =H33*G33 -> 2450
A34: Бананы мини | E34: 100 | F34: =E34*H34/$D$10 -> 46.153846 | G34: 75 | H34: 60 | I34: =H34*G34 -> 4500
A35: Слива | E35: 100 | F35: =E35*H35/$D$10 -> 30.769231 | G35: 180 | H35: 40 | I35: =H35*G35 -> 7200
A36: Итого кухня | J36: =SUM(I15:I35) -> 65150
A37: Итого грамм на персону без напитков | J37: =SUM(F13:F35) -> 413.84615
A38: Безалкогольные напитки
A39: Наименование | E39: Выход /гр | F39: Грамм /чел | G39: Цена | H39: Кол-во | I39: Сумма
A40: Чай пакетированный | E40: 200 | G40: 35 | H40: 80 | I40: =G40*H40 -> 2800
A41: Кофе "Эспрессо", "Американо" | E41: 30/120 | G41: 100 | H41: 100 | I41: =G41*H41 -> 10000
A42: Сливки порционные | E42: 10 | G42: 20 | H42: 100 | I42: =G42*H42 -> 2000
A43: Итого бар | J43: =SUM(I40:I42) -> 14800
A44: Аренда, услуги, логистика | J44: 11600
...

Sheet Велком 22.05
A5: Кейтеринг- меню 2026
A6: Менеджер службы кейтеринга | D6: Мероприятие | F6: Тайминг | I6: Выбранный зал
F7: Сбор гостей | G7: Начало | H7: Окон чание
A8: Лесников Михаил | D8: Кофе Брейк | I8: СБЕР, Советская 34
A9: Дата проведения | B9: Рассадка | D9: Кол-во | E9: Аванс | F9: Дата внесения | G9: Форма оплаты | I9: Контактный телефон
A10: 46164 | D10: 130
A11: ФИО заказчика/ наименование организации | E11: E-mail | I11: Примечания
A12: Ольга Лукина
A13: Выпечка
A14: Наименование | E14: Выход /гр | F14: Грамм /чел | G14: Цена | H14: Кол-во | I14: Сумма
A15: Мини-пирожки
A16: Сырники со сметаной | E16: 100 | F16: =E16*H16/$D$10 -> 46.153846 | G16: 120 | H16: 60 | I16: =G16*H16 -> 7200 | K16: Мармиты
A17: Сочень с творогом | E17: 22 | F17: =E17*H17/$D$10 -> 10.153846 | G17: 90 | H17: 60 | I17: =G17*H17 -> 5400
A18: Мини-пирожок с яблоком | E18: 30 | F18: =E18*H18/$D$10 -> 13.846154 | G18: 40 | H18: 60 | I18: =G18*H18 -> 2400
A19: Мини-пирожки с мясом | E19: 30 | F19: =E19*H19/$D$10 -> 13.846154 | G19: 50 | H19: 60 | I19: =G19*H19 -> 3000
A20: СЭНДВИЧИ
A21: Наименование | E21: Выход /гр | F21: Грамм /чел | G21: Цена | H21: Кол-во | I21: Сумма
A22: 1/2 сендвича с курицей | B22: Каравай | C22: Каравай | D22: Каравай | E22: 75 | F22: =E22*H22/$D$10 -> 34.615385 | G22: 130 | H22: 60 | I22: =H22*G22 -> 7800
A23: 1/2 сендвича с мягким сыром | B23: Каравай | C23: Каравай | D23: Каравай | E23: 75 | F23: =E23*H23/$D$10 -> 34.615385 | G23: 150 | H23: 60 | I23: =H23*G23 -> 9000 | K23: подносы
A24: ДЕСЕРТЫ
A25: Наименование | E25: Выход /гр | F25: Грамм /чел | G25: Цена | H25: Кол-во | I25: Сумма
A26: Французские мини-эклеры /ваниль, шоколад, манго,мята/ | E26: 35 | F26: =E26*H26/$D$10 -> 16.153846 | G26: 120 | H26: 60 | I26: =H26*G26 -> 7200
A27: Мини-прага | B27: Палочки бисквитные к шоколадному фонтану | C27: Палочки бисквитные к шоколадному фонтану | D27: Палочки бисквитные к шоколадному фонтану | E27: 50 | F27: =E27*H27/$D$10 -> 23.076923 | G27: 90 | H27: 60 | I27: =H27*G27 -> 5400 | K27: подносы
A28: Фрукты
A29: Наименование | E29: Выход /гр | F29: Грамм /чел | G29: Цена | H29: Кол-во | I29: Сумма
A30: Яблоки сезонные ( маленькие ) | E30: 100 | F30: =E30*H30/$D$10 -> 61.538462 | G30: 35 | H30: 80 | I30: =H30*G30 -> 2800
A31: Бананы мини | E31: 100 | F31: =E31*H31/$D$10 -> 61.538462 | G31: 75 | H31: 80 | I31: =H31*G31 -> 6000
A32: Слива | E32: 100 | F32: =E32*H32/$D$10 -> 30.769231 | G32: 180 | H32: 40 | I32: =H32*G32 -> 7200
A33: Лимон нарезка | E33: 100 | F33: =E33*H33/$D$10 -> 30.769231 | G33: 90 | H33: 40 | I33: =H33*G33 -> 3600
A34: Итого кухня | J34: =SUM(I13:I33) -> 67000
A35: Итого грамм на персону без напитков | J35: =SUM(F13:F31) -> 315.53846
A36: Безалкогольные напитки
A37: Наименование | E37: Выход /гр | F37: Грамм /чел | G37: Цена | H37: Кол-во | I37: Сумма
A38: Чай пакетированный | E38: 200 | G38: 35 | H38: 80 | I38: =G38*H38 -> 2800
A39: Кофе "Эспрессо", "Американо" | E39: 30/120 | G39: 100 | H39: 100 | I39: =G39*H39 -> 10000
A40: Сливки порционные | E40: 10 | G40: 20 | H40: 100 | I40: =G40*H40 -> 2000
A41: Итого бар | J41: =SUM(I38:I40) -> 14800
A42: Аренда, услуги, логистика | J42: 11600
A43: ИТОГО ПО ВСЕМ РАЗДЕЛАМ | J43: =J34+J41+J42 -> 93400
A44: Итого по всем разделам на персону | J44: =J43/$D$11 -> #DIV/0!

Sheet Кофе Брейк 22.05
A5: Кейтеринг- меню 2026
A6: Менеджер службы кейтеринга | D6: Мероприятие | F6: Тайминг | I6: Выбранный зал
F7: Сбор гостей | G7: Начало | H7: Окон чание
A8: Лесников Михаил | D8: Кофе Брейк | I8: СБЕР, Советская 34
A9: Дата проведения | B9: Рассадка | D9: Кол-во | E9: Аванс | F9: Дата внесения | G9: Форма оплаты | I9: Контактный телефон
A10: 46164 | D10: 130
A11: ФИО заказчика/ наименование организации | E11: E-mail | I11: Примечания
A12: Ольга Лукина
A13: Закуски
A14: Эклер с куриным муссом и печеным перцем | E14: 28 | F14: =E14*H14/$D$10 -> 15.076923 | G14: 70 | H14: 70 | I14: =H14*G14 -> 4900
A15: Эклер с муссом из сыра и брусничной глазури | E15: 22 | F15: =E15*H15/$D$10 -> 11.846154 | G15: 60 | H15: 70 | I15: =H15*G15 -> 4200
A16: Тарталетка с мусом из куриной печени, печеной грушей и халвой | E16: 19 | F16: =E16*H16/$D$10 -> 10.230769 | G16: 110 | H16: 70 | I16: =H16*G16 -> 7700
A17: Десерт
A18: Наименование | E18: Выход /гр | F18: Грамм /чел | G18: Цена | H18: Кол-во | I18: Сумма
A19: Макрони в ассортименте | E19: 15 | F19: =E19*H19/$D$10 -> 6.3461538 | G19: 80 | H19: 55 | I19: =H19*G19 -> 4400
A21: Мини-медовик | B21: Палочки бисквитные к шоколадному фонтану | C21: Палочки бисквитные к шоколадному фонтану | D21: Палочки бисквитные к шоколадному фонтану | E21: 50 | F21: =E21*H21/$D$10 -> 23.076923 | G21: 60 | H21: 60 | I21: =H21*G21 -> 3600
A22: Мини-птичье молоко | B22: Палочки бисквитные к шоколадному фонтану | C22: Палочки бисквитные к шоколадному фонтану | D22: Палочки бисквитные к шоколадному фонтану | E22: 50 | F22: =E22*H22/$D$10 -> 23.076923 | G22: 65 | H22: 60 | I22: =H22*G22 -> 3900
A23: Мини-Опера | B23: Палочки бисквитные к шоколадному фонтану | C23: Палочки бисквитные к шоколадному фонтану | D23: Палочки бисквитные к шоколадному фонтану | E23: 55 | F23: =E23*H23/$D$10 -> 25.384615 | G23: 90 | H23: 60 | I23: =H23*G23 -> 5400
A24: Выпечка, бутерброды
A25: Наименование | E25: Выход /гр | F25: Грамм /чел | G25: Цена | H25: Кол-во | I25: Сумма
A26: Мини-пирожки
A27: Пирог печеный с яйцом | E27: 30 | F27: =E27*H27/$D$10 -> 13.846154 | G27: 30 | H27: 60 | I27: =H27*G27 -> 1800
A28: Мини-пирожки с картофелем | E28: 30 | F28: =E28*H28/$D$10 -> 13.846154 | G28: 30 | H28: 60 | I28: =H28*G28 -> 1800
A29: Мини-пирожок с творогом и вишней | E29: 30 | F29: =E29*H29/$D$10 -> 13.846154 | G29: 30 | H29: 60 | I29: =H29*G29 -> 1800
A30: ФРУКТЫ
A31: Лимон в нарезке | E31: 100 | F31: =H31*E31/D10 -> 30.769231 | G31: 90 | H31: 40 | I31: =H31*G31 -> 3600
A32: Виноград | E32: 100 | F32: =H31*E32/D10 -> 30.769231 | G32: 200 | H32: 50 | I32: =H32*G32 -> 10000
A33: Апельсин | E33: 100 | F33: =H33*E33/D10 -> 38.461538 | G33: 55 | H33: 50 | I33: =H33*G33 -> 2750
A34: Слива | E34: 100 | F34: =H34*E34/D10 -> 38.461538 | G34: 180 | H34: 50 | I34: =H34*G34 -> 9000
A35: Итого кухня | J35: =SUM(I13:I34) -> 64850
A36: Итого грамм на персону без напитков | J36: =SUM(F13:F34) -> 295.03846
A37: Безалкогольные напитки
A38: Наименование | E38: Выход /гр | F38: Грамм /чел | G38: Цена | H38: Кол-во | I38: Сумма
A39: Чай пакетированный | E39: 200 | G39: 35 | H39: 80 | I39: =G39*H39 -> 2800
A40: Кофе "Эспрессо", "Американо" | E40: 30/120 | G40: 100 | H40: 80 | I40: =G40*H40 -> 8000
A41: Сливки порционные | E41: 10 | G41: 20 | H41: 80 | I41: =G41*H41 -> 1600
A42: Итого бар | J42: =SUM(I39:I41) -> 12400
A43: Аренда, услуги, логистика | J43: 11650
A44: ИТОГО ПО ВСЕМ РАЗДЕЛАМ | J44: =J35+J42+J43 -> 88900
A45: Итого по всем разделам на персону | J45: =J44/$D$10 -> 683.84615

Sheet СВОДКА
A5: Дата питания | C5: Кофе брейк | D5: Велком | E5: Кофе брейк | F5: ИТОГО
A6: Питание 19.05.26 | C6: ='Кофе Брейк полдник 19.05'!J46 -> 112800 | D6: ='Велком 19.05'!J42 -> 98200 | E6: ='Кофе Брейк обед 19.05'!J45 -> 97800 | F6: =E6+D6+C6 -> 308800
A7: Питание 20.05.26 | D7: ='Велком 20.05'!J42 -> 94750 | E7: ='Кофе Брейк обед 20.05'!J44 -> 117050 | F7: =E7+D7 -> 211800
A8: Питание 21.05.26 | D8: ='Велком 21.05'!J46 -> 110550 | E8: ='Кофе Брейк Обед 21.05'!J45 -> 91550 | F8: =E8+D8 -> 202100
A9: Питание 22.05.26 | D9: ='Велком 22.05'!J43 -> 93400 | E9: ='Кофе Брейк 22.05'!J44 -> 88900 | F9: =E9+D9 -> 182300
A11: Общая сумма питания: | F11: =SUM(F6:F10) -> 905000
E14: =F11 -> 905000

Sheet Услуги
A1: Услуги на проведения мероприятия на день:
A2: Менеджер службы кейтеринга | D2: Мероприятие | F2: Тайминг | I2: Выбранный зал
F3: Сбор гостей | G3: Начало | H3: Окон чание
A4: Лесников Михаил Андреевич | D4: Кофе брейк | I4: СБЕР
A5: Дата проведения | B5: Рассадка | D5: Кол-во | E5: Аванс | F5: Дата внесения | G5: Форма оплаты | I5: Контактный телефон
A6: 46161 | D6: 130
A7: ФИО заказчика/ наименование организации | E7: E-mail | I7: Примечания
A9: Услуги
A10: Наименование | E10: Кол-во сотрудников | F10: Кол-во | G10: Ставка | H10: Сумма
A11: Погрузо/разгрузочные работы | E11: 1 | F11: 2 | G11: 700 | H11: =F11*E11*G11 -> 1400
A12: Логистика (машина) | F12: 3 | G12: 1200 | H12: =G12*F12 -> 3600
A13: Текстиль | F13: 8 | G13: 500 | H13: =G13*F13 -> 4000
A14: Услуги официанта | E14: 2 | F14: 6 | G14: 750 | H14: =G14*F14*E14 -> 9000
A15: Одноразовая посуда ( вилка,тарелка ЭКО,Стаканчик бумажный 0,25 л, палочка мешалочка ) | F15: 260 | G15: 20 | H15: =G15*F15 -> 5200
F17: Итого услуг: | J17: =SUM(H11:H15) -> 23200
G18: Из расчета на человека: | J18: =J17/D6 -> 178.46154

Sheet Заявка Сбер столовая
A2: Минни пицца | E2: 90 | G2: 120 | H2: 70 | I2: 19.05 к 08:00
A3: Нон с сыром | E3: 90 | F3: =E3*H3/$D$10 -> #DIV/0! | G3: 110 | H3: 70 | I3: 19.05 к 08:00
A4: Сырники со сметаной | E4: 100 | F4: =E4*H4/$D$10 -> #DIV/0! | G4: 120 | H4: 70 | I4: 20.05 к 08:00
A5: Минни пицца | E5: 90 | F5: =E5*H5/$D$10 -> #DIV/0! | G5: 120 | H5: 60 | I5: 21.05 к 08:00
A6: Сырники со сметаной | E6: 100 | F6: =E6*H6/$D$10 -> #DIV/0! | G6: 120 | H6: 60 | I6: 22.05 к 08:00

Sheet Лист14
